root - ERROR - caught at main
Traceback (most recent call last):
  File "main.py", line 16, in <module>
  File "main.py", line 12, in main
  File "project\control\controller.py", line 47, in run
  File "project\control\controller.py", line 77, in quit
NameError: name 'quit' is not defined
